Workbook

Sheet NORTH EAST ZONE
A1: MANIPUR
A2: Age Group | B2: MALES | D2: FEMALES
B3: Males Number | C3: Males % | D3: Females Number | E3: Females % | U3: Region | V3: Total
A4: 00-04 | B4: 724965 | C4: 9.2 | D4: 666066 | E4: 8.56 | H4: North East Zone Male and Females | U4: MANIPUR | V4: 15778153
A5: 05-09 | B5: 803153 | C5: 10.19 | D5: 781315 | E5: 10.04 | U5: MIZORAM | V5: 5862530
A6: 10-14 | B6: 867063 | C6: 11 | D6: 818015 | E6: 10.51 | H6: Region | I6: Males | J6: Females | K6: Total | U6: SIKKIM | V6: 3324050
A7: 15-19 | B7: 860268 | C7: 10.91 | D7: 773938 | E7: 9.95 | H7: =A1 -> MANIPUR | I7: =B20 -> 7922747 | J7: =D20 -> 7855406 | K7: =SUM(I7:J7) -> 15778153 | U7: MEGHALAYA | V7: 10019395
A8: 20-24 | B8: 759101 | C8: 9.64 | D8: 773883 | E8: 9.89 | H8: =A24 -> MIZORAM | I8: =B43 -> 2975025 | J8: =D43 -> 2887505 | K8: =SUM(I8:J8) -> 5862530 | U8: TRIPURA | V8: 19556195
A9: 25-29 | B9: 742709 | C9: 9.42 | D9: 764680 | E9: 9.82 | H9: =A47 -> SIKKIM | I9: =B66 -> 1738066 | J9: =D66 -> 1585984 | K9: =SUM(I9:J9) -> 3324050 | U9: Total | V9: 54540323
A10: 30-34 | B10: 603809 | C10: 7.62 | D10: 627438 | E10: 8.06 | H10: =A69 -> MEGHALAYA | I10: =B88 -> 5033991 | J10: =D88 -> 4985404 | K10: =SUM(I10:J10) -> 10019395
A11: 35-39 | B11: 539573 | C11: 6.85 | D11: 593571 | E11: 7.63 | H11: =A91 -> TRIPURA | I11: =B110 -> 9871616 | J11: =D110 -> 9684579 | K11: =SUM(I11:J11) -> 19556195
A12: 40-44 | B12: 483326 | C12: 6.13 | D12: 482314 | E12: 6.2 | H12: Total | I12: =SUM(I7:I11) -> 27541445 | J12: =SUM(J7:J11) -> 26998878 | K12: =SUM(K7:K11) -> 54540323
A13: 45-49 | B13: 414860 | C13: 5.31 | D13: 416777 | E13: 5.37
A14: 50-54 | B14: 343037 | C14: 4.35 | D14: 344576 | E14: 4.43
A15: 55-59 | B15: 260980 | C15: 3.31 | D15: 255864 | E15: 3.29 | H15: North East Zone Age Wise Analysis
A16: 60-64 | B16: 200854 | C16: 2.64 | D16: 200492 | E16: 2.58
A17: 65-69 | B17: 126998 | C17: 1.61 | D17: 126469 | E17: 1.65 | H17: Age Group | I17: Males | J17: Females
A18: 70-74 | B18: 88614 | C18: 1.12 | D18: 94167 | E18: 1.21 | H18: 00-04 | I18: =B4+B27+B50+B72+B94 -> 2740205 | J18: =D4+D27+D50+D72+D94 -> 2607412 | K18: =SUM(I18:J18) -> 5347617
A19: 75+ | B19: 103437 | C19: 1.36 | D19: 135841 | E19: 1.74 | H19: 05-09 | I19: =B5+B28+B51+B73+B95 -> 2768364 | J19: =D5+D28+D51+D73+D95 -> 2691460 | K19: =SUM(I19:J19) -> 5459824
A20: TOTAL | B20: =SUM(B4:B19) -> 7922747 | C20: =SUM(C4:C19) -> 100.66 | D20: =SUM(D4:D19) -> 7855406 | E20: =SUM(E4:E19) -> 100.93 | H20: 10-14 | I20: =B6+B29+B52+B74+B96 -> 2811565 | J20: =D6+D29+D52+D74+D96 -> 2713052 | K20: =SUM(I20:J20) -> 5524617
H21: 15-19 | I21: =B7+B30+B53+B75+B97 -> 2810113 | J21: =D7+D30+D53+D75+D97 -> 2722659 | K21: =SUM(I21:J21) -> 5532772
H22: 20-24 | I22: =B8+B31+B54+B76+B98 -> 2772607 | J22: =D8+D31+D54+D76+D98 -> 2789027 | K22: =SUM(I22:J22) -> 5561634
H23: 25-29 | I23: =B9+B32+B55+B77+B99 -> 2597722 | J23: =D9+D32+D55+D77+D99 -> 2584160 | K23: =SUM(I23:J23) -> 5181882
A24: MIZORAM | H24: 30-34 | I24: =B10+B33+B56+B78+B100 -> 2200092 | J24: =D10+D33+D56+D78+D100 -> 2189502 | K24: =SUM(I24:J24) -> 4389594
A25: AGE GROUP | B25: MALES | D25: FEMALES | H25: 35-39 | I25: =B11+B34+B57+B79+B101 -> 1913468 | J25: =D11+D34+D57+D79+D101 -> 1899935 | K25: =SUM(I25:J25) -> 3813403
B26: NUMBER | C26: PERCENTAGE% | D26: NUMBER | E26: PERCENTAGE% | H26: 40-44 | I26: =B12+B35+B58+B80+B102 -> 1667442 | J26: =D12+D35+D58+D80+D102 -> 1616660 | K26: =SUM(I26:J26) -> 3284102
A27: 00-04 | B27: 327628 | C27: 11.07 | D27: 318013 | E27: 10.86 | H27: 45-49 | I27: =B13+B36+B59+B81+B103 -> 1431267 | J27: =D13+D36+D59+D81+D103 -> 1390419 | K27: =SUM(I27:J27) -> 2821686
A28: 05-09 | B28: 321219 | C28: 10.85 | D28: 310031 | E28: 10.67 | H28: 50-54 | I28: =B14+B37+B60+B82+B104 -> 1169733 | J28: =D14+D37+D60+D82+D104 -> 1106517 | K28: =SUM(I28:J28) -> 2276250
A29: 10-14 | B29: 305838 | C29: 10.34 | D29: 298739 | E29: 10.2 | H29: 55-59 | I29: =B15+B38+B61+B83+B105 -> 850823 | J29: =D15+D38+D61+D83+D105 -> 782961 | K29: =SUM(I29:J29) -> 1633784
A30: 15-19 | B30: 291587 | C30: 9.85 | D30: 280011 | E30: 9.35 | H30: 60-64 | I30: =B16+B39+B62+B84+B106 -> 662607 | J30: =D16+D39+D62+D84+D106 -> 647652 | K30: =SUM(I30:J30) -> 1310259
A31: 20-24 | B31: 291587 | C31: 9.85 | D31: 280011 | E31: 9.35 | H31: 65-69 | I31: =B17+B40+B63+B85+B107 -> 445572 | J31: =D17+D40+D63+D85+D107 -> 453734 | K31: =SUM(I31:J31) -> 899306
A32: 25-29 | B32: 281186 | C32: 9.51 | D32: 269022 | E32: 9.18 | H32: 70-74 | I32: =B18+B41+B64+B86+B108 -> 314711 | J32: =D18+D41+D64+D86+D108 -> 331877 | K32: =SUM(I32:J32) -> 646588
A33: 30-34 | B33: 245409 | C33: 8.3 | D33: 238603 | E33: 8.11 | H33: 75+ | I33: =B19+B42+B65+B87+B109 -> 385154 | J33: =D19+D42+D65+D87+D109 -> 471851 | K33: =SUM(I33:J33) -> 857005
A34: 35-39 | B34: 195063 | C34: 6.59 | D34: 190713 | E34: 6.51 | H34: TOTAL | I34: =SUM(I18:I33) -> 27541445 | J34: =SUM(J18:J33) -> 26998878 | K34: =SUM(I34:J34) -> 54540323
A35: 40-44 | B35: 159943 | C35: 5.4 | D35: 152683 | E35: 5.21
A36: 45-49 | B36: 149964 | C36: 5.07 | D36: 148701 | E36: 5.11
A37: 50-54 | B37: 124218 | C37: 4.2 | D37: 122974 | E37: 4.2
A38: 55-59 | B38: 90935 | C38: 3.07 | D38: 86457 | E38: 2.95
A39: 60-64 | B39: 69253 | C39: 2.34 | D39: 68674 | E39: 2.34
A40: 65-69 | B40: 44088 | C40: 1.49 | D40: 44350 | E40: 1.51
...

Sheet WEST ZONE
A1: GUJARAT
A2: Age Group | B2: MALES | D2: FEMALES
B3: Males Number | C3: Males % | D3: Females Number | E3: Females %
A4: 00-04 | B4: 1260412 | C4: 7.71 | D4: 1107996 | E4: 7.51
A5: 05-09 | B5: 1374616 | C5: 8.41 | D5: 1239667 | E5: 8.4
A6: 10-14 | B6: 1548110 | C6: 9.52 | D6: 1169842 | E6: 7.91
A7: 15-19 | B7: 1528616 | C7: 9.39 | D7: 1366308 | E7: 9.23 | G7: North East Zone Male and Females
A8: 20-24 | B8: 1586709 | C8: 9.76 | D8: 1409547 | E8: 9.54
A9: 25-29 | B9: 1345802 | C9: 8.23 | D9: 1258310 | E9: 8.51 | G9: Region | H9: Males | I9: Females | J9: Total | M9: Region | N9: Total
A10: 30-34 | B10: 1218190 | C10: 7.47 | D10: 1139703 | E10: 7.72 | G10: =A1 -> GUJARAT | H10: =B20 -> 14782142 | I10: =D20 -> 13386520 | J10: =H10+I10 -> 28168662 | M10: GUJARAT | N10: 28168662
A11: 35-39 | B11: 1072416 | C11: 6.56 | D11: 1029897 | E11: 6.98 | G11: =A23 -> MAHARASHTRA | H11: =B42 -> 31653901 | I11: =D42 -> 29554975 | J11: =H11+I11 -> 61208876 | M11: MAHARASHTRA | N11: 122417752
A12: 40-44 | B12: 981787 | C12: 6 | D12: 960987 | E12: 6.51 | G12: Total | H12: =SUM(H10:H11) -> 46436043 | I12: =SUM(I10:I11) -> 42941495 | J12: =SUM(J10:J11) -> 89377538 | M12: Total | N12: 150586414
A13: 45-49 | B13: 860957 | C13: 5.29 | D13: 784320 | E13: 5.3
A14: 50-54 | B14: 693497 | C14: 4.24 | D14: 617430 | E14: 4.18
A15: 55-59 | B15: 514190 | C15: 3.14 | D15: 469911 | E15: 3.18 | G15: North East Zone Age Wise Analysis
A16: 60-64 | B16: 317853 | C16: 1.94 | D16: 301680 | E16: 2.04
A17: 65-69 | B17: 220743 | C17: 1.35 | D17: 230295 | E17: 1.56 | G17: Age Group | H17: Males | I17: Females
A18: 70-74 | B18: 258244 | C18: 1.58 | D18: 300627 | E18: 2.04 | G18: 00-04 | H18: =B4+B26 -> 3687945 | I18: =D4+D26 -> 3260411 | J18: =H18+I18 -> 6948356
A19: 75+ | B19: 0 | C19: 0 | D19: 0 | E19: 0 | G19: 05-09 | H19: =B5+B27 -> 3872902 | I19: =D5+D27 -> 3480809 | J19: =H19+I19 -> 7353711
A20: TOTAL | B20: 14782142 | C20: 90.59 | D20: 13386520 | E20: 90.61 | G20: 10-14 | H20: =B6+B28 -> 4170524 | I20: =D6+D28 -> 3510144.5 | J20: =H20+I20 -> 7680668.5
G21: 15-19 | H21: =B7+B29 -> 4271080.5 | I21: =D7+D29 -> 3883339.5 | J21: =H21+I21 -> 8154420
G22: 20-24 | H22: =B8+B30 -> 5123992 | I22: =D8+D30 -> 4443172 | J22: =H22+I22 -> 9567164
A23: MAHARASHTRA | G23: 25-29 | H23: =B9+B31 -> 4399169.5 | I23: =D9+D31 -> 4153636 | J23: =H23+I23 -> 8552805.5
A24: Age Group | B24: MALES | D24: FEMALES | G24: 30-34 | H24: =B10+B32 -> 3846193.5 | I24: =D10+D32 -> 3777274.5 | J24: =H24+I24 -> 7623468
B25: Males Number | C25: Males % | D25: Females Number | E25: Females % | G25: 35-39 | H25: =B11+B33 -> 3456960 | I25: =D11+D33 -> 3519775 | J25: =H25+I25 -> 6976735
A26: 00-04 | B26: 2427533 | C26: 0.076689853 | D26: 2152415 | E26: 0.072827502 | G26: 40-44 | H26: =B12+B34 -> 3173189 | I26: =D12+D34 -> 2974667 | J26: =H26+I26 -> 6147856 | L26: 1213766.5 | M26: 1076207.5
A27: 05-09 | B27: 2498286 | C27: 0.078925059 | D27: 2241142 | E27: 0.075829602 | G27: 45-49 | H27: =B13+B35 -> 2714536 | I27: =D13+D35 -> 2502935.5 | J27: =H27+I27 -> 5217471.5 | L27: 1249143 | M27: 1120571
A28: 10-14 | B28: 2622414 | C28: 0.082846471 | D28: 2340302.5 | E28: 0.079184723 | G28: 50-54 | H28: =B14+B36 -> 2247127.5 | I28: =D14+D36 -> 1995714.5 | J28: =H28+I28 -> 4242842 | L28: 1311207 | M28: 1170151.2
A29: 15-19 | B29: 2742464.5 | C29: 0.086639069 | D29: 2517031.5 | E29: 0.085164393 | G29: 55-59 | H29: =B15+B37 -> 1736518 | I29: =D15+D37 -> 1605927.5 | J29: =H29+I29 -> 3342445.5 | L29: 1371232.2 | M29: 1258515.8
A30: 20-24 | B30: 3537283 | C30: 0.11174872 | D30: 3033625 | E30: 0.10264346 | G30: 60-64 | H30: =B16+B38 -> 1342109 | I30: =D16+D38 -> 1301465 | J30: =H30+I30 -> 2643574 | L30: 1768641.5 | M30: 1516812.5
A31: 25-29 | B31: 3053367.5 | C31: 0.096461018 | D31: 2895326 | E31: 0.097964082 | G31: 65-69 | H31: =B17+B39 -> 981787.5 | I31: =D17+D39 -> 1006726.5 | J31: =H31+I31 -> 1988514 | L31: 1526683.8 | M31: 1447663
A32: 30-34 | B32: 2628003.5 | C32: 0.083023053 | D32: 2637571.5 | E32: 0.089242894 | G32: 70-74 | H32: =B18+B40 -> 812421.5 | I32: =D18+D40 -> 861910 | J32: =H32+I32 -> 1674331.5 | L32: 1314001.8 | M32: 1318785.8
A33: 35-39 | B33: 2384544 | C33: 0.075331758 | D33: 2489878 | E33: 0.084245647 | G33: 75+ | H33: =B19+B41 -> 599588 | I33: =D19+D41 -> 663587.5 | J33: =H33+I33 -> 1263175.5 | L33: 1192272 | M33: 1244939
A34: 40-44 | B34: 2191402 | C34: 0.069230077 | D34: 2013680 | E34: 0.068133368 | G34: TOTAL | H34: =B20+B42 -> 46436043 | I34: =D20+D42 -> 42941495 | J34: =H34+I34 -> 89377538 | L34: 1095701 | M34: 1006840
A35: 45-49 | B35: 1853579 | C35: 0.05855768 | D35: 1718615.5 | E35: 0.058149787 | L35: 926789.5 | M35: 859307.75
A36: 50-54 | B36: 1553630.5 | C36: 0.049081802 | D36: 1378284.5 | E36: 0.046634602 | L36: 776815.25 | M36: 689142.25
A37: 55-59 | B37: 1222328 | C37: 0.038615398 | D37: 1136016.5 | E37: 0.038437404 | L37: 611164 | M37: 568008.25
A38: 60-64 | B38: 1024256 | C38: 0.032357971 | D38: 999785 | E38: 0.033827977 | L38: 512128 | M38: 499892.5
A39: 65-69 | B39: 761044.5 | C39: 0.024042676 | D39: 776431.5 | E39: 0.026270755 | L39: 380522.25 | M39: 388215.75
A40: 70-74 | B40: 554177.5 | C40: 0.0175074 | D40: 561283 | E40: 0.018991151 | L40: 277088.75 | M40: 280641.5
...

Sheet CENTRAL ZONE
B2: MADHYA PRADESH
B3: Age Group | C3: MALES | E3: FEMALES
C4: Males Number | D4: Males % | E4: Females Number | F4: Females %
B5: 00-04 | C5: 346072 | D5: 8.08 | E5: 319330 | F5: 8.04
B6: 05-09 | C6: 364355 | D6: 8.51 | E6: 334710 | F6: 8.43
B7: 10-14 | C7: 402970 | D7: 9.41 | E7: 365560 | F7: 9.21 | I7: Central Zone Male and Females
B8: 15-19 | C8: 453953 | D8: 10.6 | E8: 400965 | F8: 10.1
B9: 20-24 | C9: 468728 | D9: 10.95 | E9: 433072 | F9: 10.91 | I9: Region | J9: Males | K9: Females | L9: Total | N9: Region | O9: Total
B10: 25-29 | C10: 412297 | D10: 9.63 | E10: 405088 | F10: 10.2 | I10: =B2 -> MADHYA PRADESH | J10: =C21 -> 4280917 | K10: =E21 -> 3969935 | L10: =J10+K10 -> 8250852 | N10: MADHYA PRADESH | O10: 8250852
B11: 30-34 | C11: 346808 | D11: 8.1 | E11: 332122 | F11: 8.37 | I11: Total | J11: =SUM(J10:J10) -> 4280917 | K11: =SUM(K10:K10) -> 3969935 | L11: =SUM(L10:L10) -> 8250852
B12: 35-39 | C12: 315234 | D12: 7.36 | E12: 304689 | F12: 7.67
B13: 40-44 | C13: 284759 | D13: 6.65 | E13: 261360 | F13: 6.58
B14: 45-49 | C14: 247626 | D14: 5.78 | E14: 217076 | F14: 5.47 | I14: North East Zone Age Wise Analysis
B15: 50-54 | C15: 183031 | D15: 4.28 | E15: 157479 | F15: 3.97
B16: 55-59 | C16: 130482 | D16: 3.05 | E16: 118215 | F16: 2.98 | I16: Age Group | J16: Males | K16: Females
B17: 60-64 | C17: 117306 | D17: 2.74 | E17: 115902 | F17: 2.92 | I17: 00-04 | J17: =C5 -> 346072 | K17: =E5 -> 319330 | L17: =SUM(J17:K17) -> 665402
B18: 65-69 | C18: 78868 | D18: 1.84 | E18: 77898 | F18: 1.96 | I18: 05-09 | J18: =C6 -> 364355 | K18: =E6 -> 334710 | L18: =SUM(J18:K18) -> 699065
B19: 70-74 | C19: 61387 | D19: 1.43 | E19: 56167 | F19: 1.41 | I19: 10-14 | J19: =C7 -> 402970 | K19: =E7 -> 365560 | L19: =SUM(J19:K19) -> 768530
B20: 75+ | C20: 67041 | D20: 1.57 | E20: 70302 | F20: 1.77 | I20: 15-19 | J20: =C8 -> 453953 | K20: =E8 -> 400965 | L20: =SUM(J20:K20) -> 854918
B21: TOTAL | C21: 4280917 | D21: 100 | E21: 3969935 | F21: 100 | I21: 20-24 | J21: =C9 -> 468728 | K21: =E9 -> 433072 | L21: =SUM(J21:K21) -> 901800
I22: 25-29 | J22: =C10 -> 412297 | K22: =E10 -> 405088 | L22: =SUM(J22:K22) -> 817385
I23: 30-34 | J23: =C11 -> 346808 | K23: =E11 -> 332122 | L23: =SUM(J23:K23) -> 678930
I24: 35-39 | J24: =C12 -> 315234 | K24: =E12 -> 304689 | L24: =SUM(J24:K24) -> 619923
I25: 40-44 | J25: =C13 -> 284759 | K25: =E13 -> 261360 | L25: =SUM(J25:K25) -> 546119
I26: 45-49 | J26: =C14 -> 247626 | K26: =E14 -> 217076 | L26: =SUM(J26:K26) -> 464702
I27: 50-54 | J27: =C15 -> 183031 | K27: =E15 -> 157479 | L27: =SUM(J27:K27) -> 340510
I28: 55-59 | J28: =C16 -> 130482 | K28: =E16 -> 118215 | L28: =SUM(J28:K28) -> 248697
I29: 60-64 | J29: =C17 -> 117306 | K29: =E17 -> 115902 | L29: =SUM(J29:K29) -> 233208
I30: 65-69 | J30: =C18 -> 78868 | K30: =E18 -> 77898 | L30: =SUM(J30:K30) -> 156766
I31: 70-74 | J31: =C19 -> 61387 | K31: =E19 -> 56167 | L31: =SUM(J31:K31) -> 117554
I32: 75+ | J32: =C20 -> 67041 | K32: =E20 -> 70302 | L32: =SUM(J32:K32) -> 137343
I33: TOTAL | J33: =SUM(J17:J32) -> 4280917 | K33: =SUM(K17:K32) -> 3969935 | L33: =SUM(J33:K33) -> 8250852

Sheet EAST ZONE 
A1: West Bengal
A2: AGE GROUP | B2: MALES | D2: FEMALES
B3: Males Number | C3: Males % | D3: Females Number | E3: Females % | H3: East Zone Male and Females
A4: 00-04 | B4: 467924 | C4: 5.05 | D4: 435180 | E4: 5.04
A5: 05-09 | B5: 549055 | C5: 5.92 | D5: 512886 | E5: 5.94 | H5: Region | I5: Males | J5: Females | K5: Total
A6: 10-14 | B6: 668432 | C6: 7.21 | D6: 608635 | E6: 7.05 | H6: =A1 -> West Bengal | I6: =B20 -> 9270946 | J6: =D20 -> 8637373 | K6: =SUM(I6:J6) -> 17908319
A7: 15-19 | B7: 741228 | C7: 8 | D7: 687300 | E7: 7.96 | I7: =SUM(I6) -> 9270946 | J7: =SUM(J6) -> 8637373
A8: 20-24 | B8: 790540 | C8: 8.53 | D8: 774825 | E8: 8.97
A9: 25-29 | B9: 801517 | C9: 8.65 | D9: 798539 | E9: 9.25 | H9: East Zone Total Males and Females
A10: 30-34 | B10: 767757 | C10: 8.28 | D10: 745459 | E10: 8.63
A11: 35-39 | B11: 775804 | C11: 8.37 | D11: 762879 | E11: 8.83 | H11: Age Group | I11: Males | J11: Females
A12: 40-44 | B12: 750429 | C12: 8.09 | D12: 668813 | E12: 7.74 | H12: 00-04 | I12: =B4 -> 467924 | J12: =D4 -> 435180 | K12: =SUM(I12:J12) -> 903104
A13: 45-49 | B13: 691036 | C13: 7.45 | D13: 626694 | E13: 7.26 | H13: 05-09 | I13: =B5 -> 549055 | J13: =D5 -> 512886 | K13: =SUM(I13:J13) -> 1061941
A14: 50-54 | B14: 614090 | C14: 6.62 | D14: 522746 | E14: 6.05 | H14: 10-14 | I14: =B6 -> 668432 | J14: =D6 -> 608635 | K14: =SUM(I14:J14) -> 1277067
A15: 55-59 | B15: 493790 | C15: 5.33 | D15: 421841 | E15: 4.88 | H15: 15-19 | I15: =B7 -> 741228 | J15: =D7 -> 687300 | K15: =SUM(I15:J15) -> 1428528
A16: 60-64 | B16: 412334 | C16: 4.45 | D16: 362420 | E16: 4.2 | H16: 20-24 | I16: =B8 -> 790540 | J16: =D8 -> 774825 | K16: =SUM(I16:J16) -> 1565365
A17: 65-69 | B17: 270170 | C17: 2.91 | D17: 246024 | E17: 2.85 | H17: 25-29 | I17: =B9 -> 801517 | J17: =D9 -> 798539 | K17: =SUM(I17:J17) -> 1600056
A18: 70-74 | B18: 214022 | C18: 2.31 | D18: 195316 | E18: 2.26 | H18: 30-34 | I18: =B10 -> 767757 | J18: =D10 -> 745459 | K18: =SUM(I18:J18) -> 1513216
A19: 75+ | B19: 262818 | C19: 2.83 | D19: 267816 | E19: 3.1 | H19: 35-39 | I19: =B11 -> 775804 | J19: =D11 -> 762879 | K19: =SUM(I19:J19) -> 1538683
A20: TOTAL | B20: =SUM(B4:B19) -> 9270946 | C20: =SUM(C4:C19) -> 100 | D20: =SUM(D4:D19) -> 8637373 | E20: =SUM(E4:E19) -> 100.01 | H20: 40-44 | I20: =B12 -> 750429 | J20: =D12 -> 668813 | K20: =SUM(I20:J20) -> 1419242
H21: 45-49 | I21: =B13 -> 691036 | J21: =D13 -> 626694 | K21: =SUM(I21:J21) -> 1317730
H22: 50-54 | I22: =B14 -> 614090 | J22: =D14 -> 522746 | K22: =SUM(I22:J22) -> 1136836
H23: 55-59 | I23: =B15 -> 493790 | J23: =D15 -> 421841 | K23: =SUM(I23:J23) -> 915631
H24: 60-64 | I24: =B16 -> 412334 | J24: =D16 -> 362420 | K24: =SUM(I24:J24) -> 774754 | N24: Region | O24: Total
H25: 65-69 | I25: =B17 -> 270170 | J25: =D17 -> 246024 | K25: =SUM(I25:J25) -> 516194 | N25: =H6 -> West Bengal | O25: 17908319
H26: 70-74 | I26: =B18 -> 214022 | J26: =D18 -> 195316 | K26: =SUM(I26:J26) -> 409338
H27: 75+ | I27: =B19 -> 262818 | J27: =D19 -> 267816 | K27: =SUM(I27:J27) -> 530634
H28: TOTAL | I28: =B20 -> 9270946 | J28: =D20 -> 8637373 | K28: =SUM(I28:J28) -> 17908319

Sheet SOUTH ZONE
A1: TELANGANA
A2: AGE GROUP | B2: MALES | D2: FEMALES
B3: Males Number | C3: Males % | D3: Females Number | E3: Females % | H3: South Zone Male and Females
A4: 00-04 | B4: 536659 | C4: 8.79 | D4: 481700 | E4: 8.2
A5: 05-09 | B5: 529645 | C5: 8.68 | D5: 482961 | E5: 8.22 | H5: Region | I5: Males | J5: Females | K5: Total
A6: 10-14 | B6: 554264 | C6: 9.08 | D6: 511179 | E6: 8.7 | H6: =A1 -> TELANGANA | I6: =B20 -> 6105012 | J6: =D20 -> 5876194 | K6: =SUM(I6:J6) -> 11981206
A7: 15-19 | B7: 557914 | C7: 9.14 | D7: 524476 | E7: 8.93 | H7: =A23 -> TAMIL NADU | I7: =B42 -> 11878264 | J7: =D42 -> 11884496 | K7: =SUM(I7:J7) -> 23762760
A8: 20-24 | B8: 608182 | C8: 9.96 | D8: 667316 | E8: 11.36 | H8: =A45 -> KARNATAKA | I8: =B64 -> 13657989 | J8: =D64 -> 12649689 | K8: =SUM(I8:J8) -> 26307678
A9: 25-29 | B9: 608772 | C9: 9.97 | D9: 658960 | E9: 11.21 | I9: =SUM(I6:I8) -> 31641265 | J9: =SUM(J6:J8) -> 30410379 | K9: =SUM(K6:K8) -> 62051644
A10: 30-34 | B10: 552547 | C10: 9.05 | D10: 541113 | E10: 9.21
A11: 35-39 | B11: 474927 | C11: 7.78 | D11: 448062 | E11: 7.63
A12: 40-44 | B12: 415600 | C12: 6.81 | D12: 391858 | E12: 6.67 | H12: South Zone Total Males and Females
A13: 45-49 | B13: 329306 | C13: 5.39 | D13: 305649 | E13: 5.2
A14: 50-54 | B14: 269254 | C14: 4.41 | D14: 244505 | E14: 4.16 | H14: Age Group | I14: Males | J14: Females
A15: 55-59 | B15: 215759 | C15: 3.53 | D15: 190110 | E15: 3.24 | H15: 00-04 | I15: =B4+B26+B48 -> 2449439 | J15: =D4+D26+D48 -> 2294628 | K15: =SUM(I15:J15) -> 4744067
A16: 60-64 | B16: 170645 | C16: 2.8 | D16: 152705 | E16: 2.6 | H16: 05-09 | I16: =B5+B27+B49 -> 2315787 | J16: =D5+D27+D49 -> 2173176 | K16: =SUM(I16:J16) -> 4488963
A17: 65-69 | B17: 110479 | C17: 1.81 | D17: 98167 | E17: 1.67 | H17: 10-14 | I17: =B6+B28+B50 -> 2377787 | J17: =D6+D28+D50 -> 2236179 | K17: =SUM(I17:J17) -> 4613966
A18: 70-74 | B18: 72447 | C18: 1.19 | D18: 68069 | E18: 1.16 | H18: 15-19 | I18: =B7+B29+B51 -> 2465238 | J18: =D7+D29+D51 -> 2346451 | K18: =SUM(I18:J18) -> 4811689
A19: 75+ | B19: 98612 | C19: 1.62 | D19: 109364 | E19: 1.86 | H19: 20-24 | I19: =B8+B30+B52 -> 3116730 | J19: =D8+D30+D52 -> 3195260 | K19: =SUM(I19:J19) -> 6311990
A20: TOTAL | B20: =SUM(B4:B19) -> 6105012 | C20: =SUM(C4:C19) -> 100.01 | D20: =SUM(D4:D19) -> 5876194 | E20: =SUM(E4:E19) -> 100.02 | H20: 25-29 | I20: =B9+B31+B53 -> 3463720 | J20: =D9+D31+D53 -> 3556704 | K20: =SUM(I20:J20) -> 7020424
H21: 30-34 | I21: =B10+B32+B54 -> 3106821 | J21: =D10+D32+D54 -> 2889728 | K21: =SUM(I21:J21) -> 5996549
H22: 35-39 | I22: =B11+B33+B55 -> 2744292 | J22: =D11+D33+D55 -> 2574956 | K22: =SUM(I22:J22) -> 5319248 | N22: Region | O22: Total
A23: TAMIL NADU | H23: 40-44 | I23: =B12+B34+B56 -> 2266831 | J23: =D12+D34+D56 -> 2056376 | K23: =SUM(I23:J23) -> 4323207 | N23: {=H6:H8} -> TELANGANA | O23: 11981206
A24: Age Group | B24: MALES | D24: FEMALES | H24: 45-49 | I24: =B13+B35+B57 -> 1907449 | J24: =D13+D35+D57 -> 1799741 | K24: =SUM(I24:J24) -> 3707190 | N24: TAMIL NADU | O24: 23762760
B25: Males Number | C25: Males % | D25: Females Number | E25: Females % | H25: 50-54 | I25: =B14+B36+B58 -> 1498630 | J25: =D14+D36+D58 -> 1402851 | K25: =SUM(I25:J25) -> 2901481 | N25: KARNATAKA | O25: 26307678
A26: 00-04 | B26: 865729 | C26: 7.29 | D26: 817122 | E26: 6.88 | H26: 55-59 | I26: =B15+B37+B59 -> 1248791 | J26: =D15+D37+D59 -> 1170242 | K26: =SUM(I26:J26) -> 2419033
A27: 05-09 | B27: 806818 | C27: 6.81 | D27: 767355 | E27: 6.46 | H27: 60-64 | I27: =B16+B38+B60 -> 1021376 | J27: =D16+D38+D60 -> 979722 | K27: =SUM(I27:J27) -> 2001098
A28: 10-14 | B28: 852549 | C28: 7.18 | D28: 809423 | E28: 6.81 | H28: 65-69 | I28: =B17+B39+B61 -> 638837 | J28: =D17+D39+D61 -> 642720 | K28: =SUM(I28:J28) -> 1281557
A29: 15-19 | B29: 881394 | C29: 7.42 | D29: 844903 | E29: 7.11 | H29: 70-74 | I29: =B18+B40+B62 -> 460740 | J29: =D18+D40+D62 -> 462818 | K29: =SUM(I29:J29) -> 923558
A30: 20-24 | B30: 1015359 | C30: 8.55 | D30: 1095047 | E30: 9.21 | H30: 75+ | I30: =B19+B41+B63 -> 558797 | J30: =D19+D41+D63 -> 628827 | K30: =SUM(I30:J30) -> 1187624
A31: 25-29 | B31: 1151901 | C31: 9.7 | D31: 1255066 | E31: 10.56 | H31: TOTAL | I31: =SUM(I15:I30) -> 31641265 | J31: =SUM(J15:J30) -> 30410379 | K31: =SUM(I31:J31) -> 62051644
A32: 30-34 | B32: 1089118 | C32: 9.17 | D32: 1096715 | E32: 9.23
A33: 35-39 | B33: 1032043 | C33: 8.69 | D33: 1052833 | E33: 8.86
A34: 40-44 | B34: 934031 | C34: 7.87 | D34: 899118 | E34: 7.57
A35: 45-49 | B35: 820375 | C35: 6.91 | D35: 807391 | E35: 6.79
A36: 50-54 | B36: 665797 | C36: 5.6 | D36: 632325 | E36: 5.32
A37: 55-59 | B37: 572283 | C37: 4.82 | D37: 532870 | E37: 4.48
A38: 60-64 | B38: 454152 | C38: 3.82 | D38: 447286 | E38: 3.76
A39: 65-69 | B39: 270434 | C39: 2.28 | D39: 296007 | E39: 2.49
A40: 70-74 | B40: 216246 | C40: 1.82 | D40: 234394 | E40: 1.97
...

Sheet North Zone
A1: PUNJAB
A2: Age Group | B2: MALES | D2: FEMALES
B3: Males Number | C3: Males % | D3: Females Number | E3: Females %
A4: 00-04 | B4: 406876 | C4: 7.67 | D4: 353240 | E4: 7.42 | H4: North Zone Male and Females
A5: 05-09 | B5: 429082 | C5: 8.08 | D5: 348633 | E5: 7.33
A6: 10-14 | B6: 483269 | C6: 9.11 | D6: 353028 | E6: 7.42 | H6: Region | I6: Males | J6: Females | K6: Total
A7: 15-19 | B7: 555818 | C7: 10.47 | D7: 430335 | E7: 9.05 | H7: =A1 -> PUNJAB | I7: =B20 -> 5307582 | J7: =D20 -> 5657477 | K7: =SUM(I7:J7) -> 10965059
A8: 20-24 | B8: 547583 | C8: 10.32 | D8: 510891 | E8: 10.74 | H8: =A23 -> DELHI | I8: =B42 -> 27621988 | J8: =D42 -> 24301032 | K8: =SUM(I8:J8) -> 51923020
A9: 25-29 | B9: 501746 | C9: 9.45 | D9: 462163 | E9: 9.71 | H9: Total | I9: =SUM(I7:I8) -> 32929570 | J9: =SUM(J7:J8) -> 29958509 | K9: =SUM(K7:K8) -> 62888079
A10: 30-34 | B10: 413416 | C10: 7.79 | D10: 383615 | E10: 8.06
A11: 35-39 | B11: 366166 | C11: 6.9 | D11: 353703 | E11: 7.43
A12: 40-44 | B12: 334160 | C12: 6.3 | D12: 336737 | E12: 7.08
A13: 45-49 | B13: 316511 | C13: 5.96 | D13: 295411 | E13: 6.21 | H13: Region | I13: Total
A14: 50-54 | B14: 246506 | C14: 4.64 | D14: 226275 | E14: 4.76 | H14: PUNJAB | I14: 10065059
A15: 55-59 | B15: 180701 | C15: 3.4 | D15: 179855 | E15: 3.78 | H15: DELHI | I15: 51923020
A16: 60-64 | B16: 182932 | C16: 3.45 | D16: 204950 | E16: 4.31
A17: 65-69 | B17: 142929 | C17: 2.69 | D17: 124507 | E17: 2.62
A18: 70-74 | B18: 94586 | C18: 1.78 | D18: 85475 | E18: 1.8
A19: 75+ | B19: 105301 | C19: 1.98 | D19: 1008659 | E19: 2.28 | H19: Age Group | I19: Males | J19: Females
A20: TOTAL | B20: 5307582 | C20: 100 | D20: 5657477 | E20: 100 | H20: 00-04 | I20: =B4+B26 -> 2574074 | J20: =D4+D26 -> 2273621 | K20: =SUM(I20:J20) -> 4847695
D21: =SUM(D4:D19) -> 5657477 | H21: 05-09 | I21: =B5+B27 -> 2880491 | J21: =D5+D27 -> 2429032 | K21: =SUM(I21:J21) -> 5309523
H22: 10-14 | I22: =B6+B28 -> 3170704 | J22: =D6+D28 -> 2599546 | K22: =SUM(I22:J22) -> 5770250
A23: DELHI | H23: 15-19 | I23: =B7+B29 -> 3369383 | J23: =D7+D29 -> 2724781 | K23: =SUM(I23:J23) -> 6094164
A24: Age Group | B24: MALES | D24: FEMALES | H24: 20-24 | I24: =B8+B30 -> 3464738 | J24: =D8+D30 -> 3069896 | K24: =SUM(I24:J24) -> 6534634
B25: Males Number | C25: Males % | D25: Females Number | E25: Females % | H25: 25-29 | I25: =B9+B31 -> 3205239 | J25: =D9+D31 -> 2942857 | K25: =SUM(I25:J25) -> 6148096
A26: 00-04 | B26: 2167198 | C26: 7.85 | D26: 1920381 | E26: 7.9 | H26: 30-34 | I26: =B10+B32 -> 2756339 | J26: =D10+D32 -> 2510601 | K26: =SUM(I26:J26) -> 5266940
A27: 05-09 | B27: 2451409 | C27: 8.87 | D27: 2080399 | E27: 8.56 | H27: 35-39 | I27: =B11+B33 -> 2525800 | J27: =D11+D33 -> 2303844 | K27: =SUM(I27:J27) -> 4829644
A28: 10-14 | B28: 2687435 | C28: 9.73 | D28: 2246518 | E28: 9.24 | H28: 40-44 | I28: =B12+B34 -> 2178950 | J28: =D12+D34 -> 1961432 | K28: =SUM(I28:J28) -> 4140382
A29: 15-19 | B29: 2813565 | C29: 10.19 | D29: 2294446 | E29: 9.44 | H29: 45-49 | I29: =B13+B35 -> 1893715 | J29: =D13+D35 -> 1643008 | K29: =SUM(I29:J29) -> 3536723
A30: 20-24 | B30: 2917155 | C30: 10.56 | D30: 2559005 | E30: 10.53 | H30: 50-54 | I30: =B14+B36 -> 1453380 | J30: =D14+D36 -> 1244599 | K30: =SUM(I30:J30) -> 2697979
A31: 25-29 | B31: 2703493 | C31: 9.79 | D31: 2480694 | E31: 10.21 | H31: 55-59 | I31: =B15+B37 -> 1058341 | J31: =D15+D37 -> 968332 | K31: =SUM(I31:J31) -> 2026673
A32: 30-34 | B32: 2342923 | C32: 8.48 | D32: 2126986 | E32: 8.75 | H32: 60-64 | I32: =B16+B38 -> 969281 | J32: =D16+D38 -> 979972 | K32: =SUM(I32:J32) -> 1949253
A33: 35-39 | B33: 2159634 | C33: 7.82 | D33: 1950141 | E33: 8.02 | H33: 65-69 | I33: =B17+B39 -> 590409 | J33: =D17+D39 -> 548492 | K33: =SUM(I33:J33) -> 1138901
A34: 40-44 | B34: 1844790 | C34: 6.68 | D34: 1624695 | E34: 6.69 | H34: 70-74 | I34: =B18+B40 -> 396902 | J34: =D18+D40 -> 390547 | K34: =SUM(I34:J34) -> 787449
A35: 45-49 | B35: 1577204 | C35: 5.71 | D35: 1347597 | E35: 5.55 | H35: 75+ | I35: =B19+B41 -> 441824 | J35: =D19+D41 -> 1367949 | K35: =SUM(I35:J35) -> 1809773
A36: 50-54 | B36: 1206874 | C36: 4.37 | D36: 1018324 | E36: 4.19 | H36: TOTAL | I36: =SUM(I20:I35) -> 32929570 | J36: =SUM(J20:J35) -> 29958509 | K36: =SUM(I36:J36) -> 62888079
A37: 55-59 | B37: 877640 | C37: 3.18 | D37: 788477 | E37: 3.24
A38: 60-64 | B38: 786349 | C38: 2.85 | D38: 775022 | E38: 3.19
A39: 65-69 | B39: 447480 | C39: 1.62 | D39: 423985 | E39: 1.74
A40: 70-74 | B40: 302316 | C40: 1.09 | D40: 305072 | E40: 1.26
...

Sheet Sheet1
A1: t-Test: Paired Two Sample for Means
B3: Variable 1 | C3: Variable 2 | G3: =_xlfn.T.TEST('Final Calc'!C5:C10,'Final Calc'!D5:D10,1,1) -> 0.020143245 | I3: Zones | J3: Total
A4: Mean | B4: 43457196 | C4: 40833305 | G4: =_xlfn.Z.TEST('Final Calc'!L5:L10,3) -> 3.1767093e-05 | I4: Central Zone | J4: 41254260
A5: Variance | B5: 2.5032353e+15 | C5: 2.2065355e+15 | I5: East Zone | J5: 89541595
A6: Observations | B6: 7 | C6: 7 | I6: North East Zone | J6: 54540323
A7: Pearson Correlation | B7: 0.99988076 | I7: North Zone | J7: 1.572202e+08
A8: Hypothesized Mean Difference | B8: 0 | I8: South Zone | J8: 1.0341941e+08
A9: df | B9: 6 | I9: West Zone | J9: 223443845
A10: t Stat | B10: 2.2046598
A11: P(T<=t) one-tail | B11: 0.034826833
A12: t Critical one-tail | B12: 1.9431803
A13: P(T<=t) two-tail | B13: 0.069653665
A14: t Critical two-tail | B14: 2.4469119

Sheet Final Calc
B2: Region Wise Males and Females
B4: Zones | C4: Males | D4: Females | E4: Total | H4: Gender | I4: Total | K4: Zones | L4: Total
B5: Central Zone | C5: ='CENTRAL ZONE'!C21 -> 4280917 | D5: ='CENTRAL ZONE'!K11 -> 3969935 | E5: =C5+D5 -> 8250852 | H5: Males | I5: =C11 -> 152100186 | K5: Central Zone | L5: =M5*E5 -> 41254260 | M5: 5
B6: East Zone | C6: ='EAST ZONE '!I7 -> 9270946 | D6: ='EAST ZONE '!J7 -> 8637373 | E6: =C6+D6 -> 17908319 | H6: Females | I6: =D11 -> 142916569 | K6: East Zone | L6: =M6*E6 -> 89541595 | M6: 5
B7: North East Zone | C7: ='NORTH EAST ZONE'!I12 -> 27541445 | D7: ='NORTH EAST ZONE'!J12 -> 26998878 | E7: =C7+D7 -> 54540323 | K7: North East Zone | L7: =M7*E7 -> 54540323 | M7: 1
B8: North Zone | C8: ='North Zone'!I9 -> 32929570 | D8: ='North Zone'!J9 -> 29958509 | E8: =C8+D8 -> 62888079 | K8: North Zone | L8: =M8*E8 -> 1.572202e+08 | M8: 2.5
B9: South Zone | C9: ='SOUTH ZONE'!I9 -> 31641265 | D9: ='SOUTH ZONE'!J9 -> 30410379 | E9: =C9+D9 -> 62051644 | K9: South Zone | L9: =M9*E9 -> 1.0341941e+08 | M9: 1.6666667
B10: West Zone | C10: ='WEST ZONE'!H12 -> 46436043 | D10: ='WEST ZONE'!I12 -> 42941495 | E10: =C10+D10 -> 89377538 | G10: Zones | H10: Males | I10: Females | J10: Total | K10: West Zone | L10: =M10*E10 -> 223443845 | M10: 2.5
B11: Total | C11: =SUM(C5:C10) -> 152100186 | D11: =SUM(D5:D10) -> 142916569 | E11: =C11+D11 -> 295016755 | G11: Central Zone | H11: 4280917 | I11: 3969935 | J11: 8250852
G12: East Zone | H12: 9270946 | I12: 8637373 | J12: 17908319
G13: North East Zone | H13: 27541445 | I13: 26998878 | J13: 54540323
G14: North Zone | H14: 32929570 | I14: 29958509 | J14: 62888079
G15: South Zone | H15: 31641265 | I15: 30410379 | J15: 62051644
G16: West Zone | H16: 46436043 | I16: 42941495 | J16: 89377538
G17: Total | H17: 152100186 | I17: 142916569 | J17: 295016755
H27: Age Group | I27: Total
H28: 00-04 | I28: =E38 -> 23456241
H29: 05-09 | I29: =E39 -> 24373027
H30: 10-14 | I30: =E40 -> 25635098
H31: 15-19 | I31: =E41 -> 26876491
H32: 20-24 | I32: =E42 -> 30442587
H33: 25-29 | I33: =E43 -> 29320648
H34: 30-34 | I34: =E44 -> 25468697
H35: 35-39 | I35: =E45 -> 23097636
H36: 40-44 | I36: =E46 -> 19860908
B37: Age Group | C37: Males | D37: Females | E37: Total | H37: 45-49 | I37: =E47 -> 17065502
B38: 00-04 | C38: 12265659 | D38: 11190582 | E38: 23456241 | H38: 50-54 | I38: =E48 -> 13595898
B39: 05-09 | C39: 12750954 | D39: 11622073 | E39: 24373027 | H39: 55-59 | I39: =E49 -> 10586264
B40: 10-14 | C40: 13601982 | D40: 12033116 | E40: 25635098 | H40: 60-64 | I40: =E50 -> 8912146
B41: 15-19 | C41: 14110996 | D41: 12765496 | E41: 26876491 | H41: 65-69 | I41: =E51 -> 5981238
B42: 20-24 | C42: 15737335 | D42: 14705252 | E42: 30442587 | H42: 70-74 | I42: =E52 -> 4558818.5
B43: 25-29 | C43: 14879664 | D43: 14440984 | E43: 29320648 | H43: 75+ | I43: =E53 -> 5785554.5
B44: 30-34 | C44: 13024010 | D44: 12444686 | E44: 25468697
B45: 35-39 | C45: 11731558 | D45: 11366078 | E45: 23097636
B46: 40-44 | C46: 10321600 | D46: 9539308 | E46: 19860908
B47: 45-49 | C47: 8885629 | D47: 8179873.5 | E47: 17065502
B48: 50-54 | C48: 7165991.5 | D48: 6429906.5 | E48: 13595898
B49: 55-59 | C49: 5518745 | D49: 5067518.5 | E49: 10586264
B50: 60-64 | C50: 4525013 | D50: 4387133 | E50: 8912146
B51: 65-69 | C51: 3005643.5 | D51: 2975594.5 | E51: 5981238
...

Sheet Sheet2
A1: Age Group | B1: Total | C1: Expected | D1: Chi Term
A2: 00-04 | B2: 23456241 | C2: =$B$19/$B$20 -> 18438547 | D2: =(B2-C2)^2/C2 -> 1365468.3
A3: 05-09 | B3: 24373027 | C3: =$B$19/$B$20 -> 18438547 | D3: =(B3-C3)^2/C3 -> 1910023.1
A4: 10-14 | B4: 25635098 | C4: =$B$19/$B$20 -> 18438547 | D4: =(B4-C4)^2/C4 -> 2808808.6
A5: 15-19 | B5: 26876491 | C5: =$B$19/$B$20 -> 18438547 | D5: =(B5-C5)^2/C5 -> 3861415.7
A6: 20-24 | B6: 30442587 | C6: =$B$19/$B$20 -> 18438547 | D6: =(B6-C6)^2/C6 -> 7814985.1
A7: 25-29 | B7: 29320648 | C7: =$B$19/$B$20 -> 18438547 | D7: =(B7-C7)^2/C7 -> 6422421.9
A8: 30-34 | B8: 25468697 | C8: =$B$19/$B$20 -> 18438547 | D8: =(B8-C8)^2/C8 -> 2680417.6
A9: 35-39 | B9: 23097636 | C9: =$B$19/$B$20 -> 18438547 | D9: =(B9-C9)^2/C9 -> 1177267.8
A10: 40-44 | B10: 19860908 | C10: =$B$19/$B$20 -> 18438547 | D10: =(B10-C10)^2/C10 -> 109721.78
A11: 45-49 | B11: 17065502 | C11: =$B$19/$B$20 -> 18438547 | D11: =(B11-C11)^2/C11 -> 102245.13
A12: 50-54 | B12: 13595898 | C12: =$B$19/$B$20 -> 18438547 | D12: =(B12-C12)^2/C12 -> 1271860
A13: 55-59 | B13: 10586264 | C13: =$B$19/$B$20 -> 18438547 | D13: =(B13-C13)^2/C13 -> 3343992.3
... A17: 75+ | B17: 5785554.5 | C17: =$B$19/$B$20 -> 18438547 | D17: =(B17-C17)^2/C17 -> 8682800.3
A19: Sum | B19: =SUM(B2:B17) -> 295016755 | D19: =SUM(D2:D17) -> 65337669
A20: count | B20: =COUNT(B2:B17) -> 16
A21: Chi Square Statistics | B21: =SUM(D2:D17) -> 65337669 | D21: =_xlfn.CHISQ.TEST(B2:B17,C2:C17) -> 0

Sheet zone based testing
A1: H0: Cancer cases are equally distributed across all zones
A2: H1: Cancer cases are not equally distributed across all zones
A4: Zones | B4: Total | C4: Expected | D4: Chi Term | G4: 26
A5: Central Zone | B5: 41254260 | C5: =$B$12/$B$13 -> 1.1156994e+08 | D5: =(B5-C5)^2/C5 -> 44315652 | G5: 22
A6: East Zone | B6: 89541595 | C6: =$B$12/$B$13 -> 1.1156994e+08 | D6: =(B6-C6)^2/C6 -> 4349270.9 | G6: 62
A7: North East Zone | B7: 54540323 | C7: =$B$12/$B$13 -> 1.1156994e+08 | D7: =(B7-C7)^2/C7 -> 29151015 | G7: 22
A8: North Zone | B8: 1.572202e+08 | C8: =$B$12/$B$13 -> 1.1156994e+08 | D8: =(B8-C8)^2/C8 -> 18678385 | G8: =SUM(G4:G7) -> 132
A9: South Zone | B9: 1.0341941e+08 | C9: =$B$12/$B$13 -> 1.1156994e+08 | D9: =(B9-C9)^2/C9 -> 595421.67 | G9: =G8/4 -> 33
A10: West Zone | B10: 223443845 | C10: =$B$12/$B$13 -> 1.1156994e+08 | D10: =(B10-C10)^2/C10 -> 1.121787e+08
A12: Total Cases | B12: =SUM(B5:B10) -> 6.6941963e+08
A13: number | B13: =COUNTA(A5:A10) -> 6 | G13: We reject the null hypothesis
A14: ChiSqStat | B14: =SUM(D5:D10) -> 2.0926845e+08 | C14: =_xlfn.CHISQ.TEST(B5:B10,C5:C10) -> 0
A15: Degree of Freedom | B15: =B13-1 -> 5
A19: Chi SQ Test | B19: =_xlfn.CHISQ.TEST(B5:B10,C5:C10) -> 0
B20: =_xlfn.CHISQ.DIST.RT(B14,B15) -> 0

Sheet Gender based testing
A1: Zones | B1: Males (X) | C1: Females (Y) | D1: X - X bar | E1: Y - Y bar | F1: (X-Xbar) *(Y-Y bar) | G1: (X-Xbar)**2
A2: Central Zone | B2: 4280917 | C2: 3969935 | D2: =B2-$B$11 -> -21069114 | E2: =C2-$C$11 -> -19849493 | F2: =D2*E2 -> 418211234370721 | G2: =D2^2 -> 443907564744996
A3: East Zone | B3: 9270946 | C3: 8637373 | D3: =B3-$B$11 -> -16079085 | E3: =C3-$C$11 -> -15182055 | F3: =D3*E3 -> 2.4411356e+14 | G3: =D3^2 -> 258536974437225
A4: North East Zone | B4: 27541445 | C4: 26998878 | D4: =B4-$B$11 -> 2191414 | E4: =C4-$C$11 -> 3179449.8 | F4: =D4*E4 -> 6.9674909e+12 | G4: =D4^2 -> 4802295319396
A5: North Zone | B5: 32929570 | C5: 29958509 | D5: =B5-$B$11 -> 7579539 | E5: =C5-$C$11 -> 6139080.8 | F5: =D5*E5 -> 4.6531403e+13 | G5: =D5^2 -> 57449411452521
A6: South Zone | B6: 31641265 | C6: 30410379 | D6: =B6-$B$11 -> 6291234 | E6: =C6-$C$11 -> 6590950.8 | F6: =D6*E6 -> 4.1465214e+13 | G6: =D6^2 -> 39579625242756
A7: West Zone | B7: 46436043 | C7: 42941495 | D7: =B7-$B$11 -> 21086012 | E7: =C7-$C$11 -> 19122067 | F7: =D7*E7 -> 4.0320813e+14 | G7: =D7^2 -> 444619902064144
A9: N | B9: =COUNT(B2:B7) -> 6 | C9: =COUNT(C2:C7) -> 6
A10: Sum | B10: =SUM(B2:B7) -> 152100186 | C10: =SUM(C2:C7) -> 142916569 | D10: =SUM(D2:D7) -> 0 | E10: =SUM(E2:E7) -> 0 | F10: =SUM(F2:F7) -> 1.160497e+15 | G10: =SUM(G2:G7) -> 1.2488958e+15
A11: Mean | B11: =AVERAGE(B2:B7) -> 25350031 | C11: =AVERAGE(C2:C7) -> 23819428 | J11: =CORREL(B2:B7,C2:C7) -> 0.99859657
A12: Mean Double Check | B12: =B10/B9 -> 25350031 | C12: =C10/C9 -> 23819428
A14: Covariance | B14: =F10/C9 -> 1.9341617e+14 | C14: =_xlfn.COVARIANCE.S(B2:B7,C2:C7) -> 2.3209941e+14
A15: Covariance double check using formula | B15: =_xlfn.COVARIANCE.P(B2:B7,C2:C7) -> 1.9341617e+14
A17: Variance | B17: =G10/B9 -> 2.081493e+14
A18: Variance using formula | B18: =_xlfn.VAR.P(B2:B7) -> 2.081493e+14 | C18: =_xlfn.VAR.P(C2:C7) -> 1.8023141e+14 | D18: =_xlfn.VAR.S(B2:B7) -> 2.4977915e+14
A20: Regression
A22: Beta 1 | B22: =B14/B17 -> 0.92921848
A24: beta not | B24: =C11-B22*B11 -> 263710.98
A25: Regression | B25: SUMMARY OUTPUT
B27: Regression Statistics
B28: Multiple R | C28: 0.99859657
B29: R Square | C29: 0.9971951
B30: Adjusted R Square | C30: 0.99649388
B31: Standard Error | C31: 870802.07
B32: Observations | C32: 6
B34: ANOVA
C35: df | D35: SS | E35: MS | F35: F | G35: Significance F
B36: Regression | C36: 1 | D36: 1.0783553e+15 | E36: 1.0783553e+15 | F36: 1422.0765 | G36: 2.9530588e-06
B37: Residual | C37: 4 | D37: 3.033185e+12 | E37: 7.5829625e+11
B38: Total | C38: 5 | D38: 1.0813885e+15
C40: Coefficients | D40: Standard Error | E40: t Stat | F40: P-value | G40: Lower 95% | H40: Upper 95% | I40: Lower 95.0% | J40: Upper 95.0%
B41: Intercept | C41: 263710.98 | D41: 718725.91 | E41: 0.36691453 | F41: 0.73226902 | G41: -1731792 | H41: 2259214 | I41: -1731792 | J41: 2259214
B42: X Variable 1 | C42: 0.92921848 | D42: 0.024640888 | E42: 37.71043 | F42: 2.9530588e-06 | G42: 0.8608044 | H42: 0.99763255 | I42: 0.8608044 | J42: 0.99763255
A46: H0: Gender and Zone are independent of each other
A47: H1: Gender and Zone are dependent on each other
A50: Observed Frequency
A51: Zones | B51: Males (X) | C51: Females (Y) | G51: Class | H51: Frequency | J51: Observed - Expected | K51: (Observed - Expected)^2/Expected
A52: Central Zone | B52: 4280917 | C52: 3969935 | D52: =SUM(B52:C52) -> 8250852 | H52: Observed | I52: Expected
A53: East Zone | B53: 9270946 | C53: 8637373 | D53: =SUM(B53:C53) -> 17908319 | G53: Central Zone Male | H53: =B52 -> 4280917 | I53: =B65 -> 4253847 | J53: =H53-I53 -> 27070.049 | K53: =(J53^2)/I53 -> 172.26467
A54: North East Zone | B54: 27541445 | C54: 26998878 | D54: =SUM(B54:C54) -> 54540323 | G54: Central Zone Female | H54: =C52 -> 3969935 | I54: =C65 -> 3997005 | J54: =H54-I54 -> -27070.049 | K54: =(J54^2)/I54 -> 183.33415
...

Sheet Correlation
A1: Zones | B1: Males (x) | C1: Females (y) | D1: x-x̄ | E1: y - ȳ | F1: (x-x̄)*(y-ȳ) | G1: (x-x̄)^2 | H1: (y-ȳ)^2
A2: Central Zone | B2: 4280917 | C2: 3969935 | D2: =B2-$B$10 -> -21069114 | E2: =C2-$C$10 -> -19849493 | F2: =D2*E2 -> 418211234370721 | G2: =D2^2 -> 443907564744996 | H2: =E2^2 -> 3.9400238e+14
A3: East Zone | B3: 9270946 | C3: 8637373 | D3: =B3-$B$10 -> -16079085 | E3: =C3-$C$10 -> -15182055 | F3: =D3*E3 -> 2.4411356e+14 | G3: =D3^2 -> 258536974437225 | H3: =E3^2 -> 2.304948e+14
A4: North East Zone | B4: 27541445 | C4: 26998878 | D4: =B4-$B$10 -> 2191414 | E4: =C4-$C$10 -> 3179449.8 | F4: =D4*E4 -> 6.9674909e+12 | G4: =D4^2 -> 4802295319396 | H4: =E4^2 -> 1.0108901e+13
A5: North Zone | B5: 32929570 | C5: 29958509 | D5: =B5-$B$10 -> 7579539 | E5: =C5-$C$10 -> 6139080.8 | F5: =D5*E5 -> 4.6531403e+13 | G5: =D5^2 -> 57449411452521 | H5: =E5^2 -> 3.7688313e+13
A6: South Zone | B6: 31641265 | C6: 30410379 | D6: =B6-$B$10 -> 6291234 | E6: =C6-$C$10 -> 6590950.8 | F6: =D6*E6 -> 4.1465214e+13 | G6: =D6^2 -> 39579625242756 | H6: =E6^2 -> 4.3440633e+13
A7: West Zone | B7: 46436043 | C7: 42941495 | D7: =B7-$B$10 -> 21086012 | E7: =C7-$C$10 -> 19122067 | F7: =D7*E7 -> 4.0320813e+14 | G7: =D7^2 -> 444619902064144 | H7: =E7^2 -> 3.6565344e+14
A9: Sum | B9: =SUM(B2:B7) -> 152100186 | C9: =SUM(C2:C7) -> 142916569 | F9: =SUM(F2:F7) -> 1.160497e+15 | G9: =SUM(G2:G7) -> 1.2488958e+15 | H9: =SUM(H2:H7) -> 1.0813885e+15
A10: mean | B10: =B9/6 -> 25350031 | C10: =C9/6 -> 23819428 | F10: =SUM(F2:F7) -> 1.160497e+15
G13: =F9/(G9*H9)^(1/2) -> 0.99859657

Sheet Sheet4
A1: North East Zone Age Wise Analysis | F1: West Zone Age Wise Distribution | K1: Central Zone Age Wise Analysis | P1: East Zone Total Males and Females | U1: South Zone Total Males and Females | Z1: North Zone
A3: Age Group | B3: Males | C3: Females | F3: Age Group | G3: Males | H3: Females | K3: Age Group | L3: Males | M3: Females | P3: Age Group | Q3: Males | R3: Females | U3: Age Group | V3: Males | W3: Females | Z3: Age Group | AA3: Males | AB3: Females
A4: 00-04 | B4: 2740205 | C4: 2607412 | D4: 5347617 | F4: 00-04 | G4: 3687945 | H4: 3260411 | I4: 6948356 | K4: 00-04 | L4: 346072 | M4: 319330 | N4: 665402 | P4: 00-04 | Q4: 467924 | R4: 435180 | S4: 903104 | U4: 00-04 | V4: 2449439 | W4: 2294628 | X4: 4744067 | Z4: 00-04 | AA4: 2574074 | AB4: 2273621 | AC4: 4847695
A5: 05-09 | B5: 2768364 | C5: 2691460 | D5: 5459824 | F5: 05-09 | G5: 3872902 | H5: 3480809 | I5: 7353711 | K5: 05-09 | L5: 364355 | M5: 334710 | N5: 699065 | P5: 05-09 | Q5: 549055 | R5: 512886 | S5: 1061941 | U5: 05-09 | V5: 2315787 | W5: 2173176 | X5: 4488963 | Z5: 05-09 | AA5: 2880491 | AB5: 2429032 | AC5: 5309523
A6: 10-14 | B6: 2811565 | C6: 2713052 | D6: 5524617 | F6: 10-14 | G6: 4170524 | H6: 3510144.5 | I6: 7680668.5 | K6: 10-14 | L6: 402970 | M6: 365560 | N6: 768530 | P6: 10-14 | Q6: 668432 | R6: 608635 | S6: 1277067 | U6: 10-14 | V6: 2377787 | W6: 2236179 | X6: 4613966 | Z6: 10-14 | AA6: 3170704 | AB6: 2599546 | AC6: 5770250
A7: 15-19 | B7: 2810113 | C7: 2722659 | D7: 5532772 | F7: 15-19 | G7: 4271080.5 | H7: 3883339.5 | I7: 8154420 | K7: 15-19 | L7: 453953 | M7: 400965 | N7: 854918 | P7: 15-19 | Q7: 741228 | R7: 687300 | S7: 1428528 | U7: 15-19 | V7: 2465238 | W7: 2346451 | X7: 4811689 | Z7: 15-19 | AA7: 3369383 | AB7: 2724781 | AC7: 6094164
A8: 20-24 | B8: 2772607 | C8: 2789027 | D8: 5561634 | F8: 20-24 | G8: 5123992 | H8: 4443172 | I8: 9567164 | K8: 20-24 | L8: 468728 | M8: 433072 | N8: 901800 | P8: 20-24 | Q8: 790540 | R8: 774825 | S8: 1565365 | U8: 20-24 | V8: 3116730 | W8: 3195260 | X8: 6311990 | Z8: 20-24 | AA8: 3464738 | AB8: 3069896 | AC8: 6534634
A9: 25-29 | B9: 2597722 | C9: 2584160 | D9: 5181882 | F9: 25-29 | G9: 4399169.5 | H9: 4153636 | I9: 8552805.5 | K9: 25-29 | L9: 412297 | M9: 405088 | N9: 817385 | P9: 25-29 | Q9: 801517 | R9: 798539 | S9: 1600056 | U9: 25-29 | V9: 3463720 | W9: 3556704 | X9: 7020424 | Z9: 25-29 | AA9: 3205239 | AB9: 2942857 | AC9: 6148096
A10: 30-34 | B10: 2200092 | C10: 2189502 | D10: 4389594 | F10: 30-34 | G10: 3846193.5 | H10: 3777274.5 | I10: 7623468 | K10: 30-34 | L10: 346808 | M10: 332122 | N10: 678930 | P10: 30-34 | Q10: 767757 | R10: 745459 | S10: 1513216 | U10: 30-34 | V10: 3106821 | W10: 2889728 | X10: 5996549 | Z10: 30-34 | AA10: 2756339 | AB10: 2510601 | AC10: 5266940
A11: 35-39 | B11: 1913468 | C11: 1899935 | D11: 3813403 | F11: 35-39 | G11: 3456960 | H11: 3519775 | I11: 6976735 | K11: 35-39 | L11: 315234 | M11: 304689 | N11: 619923 | P11: 35-39 | Q11: 775804 | R11: 762879 | S11: 1538683 | U11: 35-39 | V11: 2744292 | W11: 2574956 | X11: 5319248 | Z11: 35-39 | AA11: 2525800 | AB11: 2303844 | AC11: 4829644
A12: 40-44 | B12: 1667442 | C12: 1616660 | D12: 3284102 | F12: 40-44 | G12: 3173189 | H12: 2974667 | I12: 6147856 | K12: 40-44 | L12: 284759 | M12: 261360 | N12: 546119 | P12: 40-44 | Q12: 750429 | R12: 668813 | S12: 1419242 | U12: 40-44 | V12: 2266831 | W12: 2056376 | X12: 4323207 | Z12: 40-44 | AA12: 2178950 | AB12: 1961432 | AC12: 4140382
A13: 45-49 | B13: 1431267 | C13: 1390419 | D13: 2821686 | F13: 45-49 | G13: 2714536 | H13: 2502935.5 | I13: 5217471.5 | K13: 45-49 | L13: 247626 | M13: 217076 | N13: 464702 | P13: 45-49 | Q13: 691036 | R13: 626694 | S13: 1317730 | U13: 45-49 | V13: 1907449 | W13: 1799741 | X13: 3707190 | Z13: 45-49 | AA13: 1893715 | AB13: 1643008 | AC13: 3536723
A14: 50-54 | B14: 1169733 | C14: 1106517 | D14: 2276250 | F14: 50-54 | G14: 2247127.5 | H14: 1995714.5 | I14: 4242842 | K14: 50-54 | L14: 183031 | M14: 157479 | N14: 340510 | P14: 50-54 | Q14: 614090 | R14: 522746 | S14: 1136836 | U14: 50-54 | V14: 1498630 | W14: 1402851 | X14: 2901481 | Z14: 50-54 | AA14: 1453380 | AB14: 1244599 | AC14: 2697979
A15: 55-59 | B15: 850823 | C15: 782961 | D15: 1633784 | F15: 55-59 | G15: 1736518 | H15: 1605927.5 | I15: 3342445.5 | K15: 55-59 | L15: 130482 | M15: 118215 | N15: 248697 | P15: 55-59 | Q15: 493790 | R15: 421841 | S15: 915631 | U15: 55-59 | V15: 1248791 | W15: 1170242 | X15: 2419033 | Z15: 55-59 | AA15: 1058341 | AB15: 968332 | AC15: 2026673
... A20: TOTAL | B20: 27541445 | C20: 26998878 | D20: 54540323 | F20: TOTAL | G20: 46436043 | H20: 42941495 | I20: 89377538 | K20: TOTAL | L20: 4280917 | M20: 3969935 | N20: 8250852 | P20: TOTAL | Q20: 9270946 | R20: 8637373 | S20: 17908319 | U20: TOTAL | V20: 31641265 | W20: 30410379 | X20: 62051644 | Z20: TOTAL | AA20: 32929570 | AB20: 29958509 | AC20: 62888079
I26: Age Group | J26: Males | K26: Females | L26: Total
I27: 00-04 | J27: =B4+G4+L4+Q4+V4+AA4 -> 12265659 | K27: =C4+H4+M4+R4+W4+AB4 -> 11190582 | L27: =SUM(J27:K27) -> 23456241
I28: 05-09 | J28: =B5+G5+L5+Q5+V5+AA5 -> 12750954 | K28: =C5+H5+M5+R5+W5+AB5 -> 11622073 | L28: =SUM(J28:K28) -> 24373027
I29: 10-14 | J29: =B6+G6+L6+Q6+V6+AA6 -> 13601982 | K29: =C6+H6+M6+R6+W6+AB6 -> 12033116 | L29: =SUM(J29:K29) -> 25635098
I30: 15-19 | J30: =B7+G7+L7+Q7+V7+AA7 -> 14110996 | K30: =C7+H7+M7+R7+W7+AB7 -> 12765496 | L30: =SUM(J30:K30) -> 26876491
I31: 20-24 | J31: =B8+G8+L8+Q8+V8+AA8 -> 15737335 | K31: =C8+H8+M8+R8+W8+AB8 -> 14705252 | L31: =SUM(J31:K31) -> 30442587
I32: 25-29 | J32: =B9+G9+L9+Q9+V9+AA9 -> 14879664 | K32: =C9+H9+M9+R9+W9+AB9 -> 14440984 | L32: =SUM(J32:K32) -> 29320648
I33: 30-34 | J33: =B10+G10+L10+Q10+V10+AA10 -> 13024010 | K33: =C10+H10+M10+R10+W10+AB10 -> 12444686 | L33: =SUM(J33:K33) -> 25468697
I34: 35-39 | J34: =B11+G11+L11+Q11+V11+AA11 -> 11731558 | K34: =C11+H11+M11+R11+W11+AB11 -> 11366078 | L34: =SUM(J34:K34) -> 23097636
I35: 40-44 | J35: =B12+G12+L12+Q12+V12+AA12 -> 10321600 | K35: =C12+H12+M12+R12+W12+AB12 -> 9539308 | L35: =SUM(J35:K35) -> 19860908
I36: 45-49 | J36: =B13+G13+L13+Q13+V13+AA13 -> 8885629 | K36: =C13+H13+M13+R13+W13+AB13 -> 8179873.5 | L36: =SUM(J36:K36) -> 17065502
I37: 50-54 | J37: =B14+G14+L14+Q14+V14+AA14 -> 7165991.5 | K37: =C14+H14+M14+R14+W14+AB14 -> 6429906.5 | L37: =SUM(J37:K37) -> 13595898
I38: 55-59 | J38: =B15+G15+L15+Q15+V15+AA15 -> 5518745 | K38: =C15+H15+M15+R15+W15+AB15 -> 5067518.5 | L38: =SUM(J38:K38) -> 10586264
... I42: 75+ | J42: =B19+G19+L19+Q19+V19+AA19 -> 2315222 | K42: =C19+H19+M19+R19+W19+AB19 -> 3470332.5 | L42: =SUM(J42:K42) -> 5785554.5
I43: TOTAL | J43: =SUM(J27:J42) -> 152100186 | K43: =SUM(K27:K42) -> 142916569 | L43: =SUM(J43:K43) -> 295016755

Sheet Sheet3
A1: North East Zone Male and Females | F1: West Zone Male and Females | K1: Central Zone Male and Females | P1: East Zone Male and Females
A3: Region | B3: Males | C3: Females | D3: Total | F3: Region | G3: Males | H3: Females | I3: Total | K3: Region | L3: Males | M3: Females | N3: Total | P3: Region | Q3: Males | R3: Females | S3: Total
A4: MANIPUR | B4: 7922747 | C4: 7855406 | D4: 15778153 | F4: GUJARAT | G4: 14782142 | H4: 13386520 | I4: 28168662 | K4: MADHYA PRADESH | L4: 4280917 | M4: 3969935 | N4: 8250852 | P4: West Bengal | Q4: 9270946 | R4: 8637373 | S4: 17908319
A5: MIZORAM | B5: 2975025 | C5: 2887505 | D5: 5862530 | F5: MAHARASHTRA | G5: 31653901 | H5: 29554975 | I5: 61208876 | K5: Total | L5: 4280917 | M5: 3969935 | N5: 8250852 | Q5: 9270946 | R5: 8637373
A6: SIKKIM | B6: 1738066 | C6: 1585984 | D6: 3324050 | F6: Total | G6: 46436043 | H6: 42941495 | I6: 89377538
A7: MEGHALAYA | B7: 5033991 | C7: 4985404 | D7: 10019395
A8: TRIPURA | B8: 9871616 | C8: 9684579 | D8: 19556195 | P8: South Zone Male and Females
A9: Total | B9: 27541445 | C9: 26998878 | D9: 54540323
K10: North Zone Male and Females | P10: Region | Q10: Males | R10: Females | S10: Total
P11: TELANGANA | Q11: 6105012 | R11: 5876194 | S11: 11981206
K12: Region | L12: Males | M12: Females | N12: Total | P12: TAMIL NADU | Q12: 11878264 | R12: 11884496 | S12: 23762760
K13: PUNJAB | L13: 5307582 | M13: 5657477 | N13: 10965059 | P13: KARNATAKA | Q13: 13657989 | R13: 12649689 | S13: 26307678
K14: DELHI | L14: 27621988 | M14: 24301032 | N14: 51923020 | Q14: 31641265 | R14: 30410379 | S14: 62051644
K15: Total | L15: 32929570 | M15: 29958509 | N15: 62888079
B21: Zones | C21: Males | D21: Females | E21: Total
B22: Central Zone | C22: =L5 -> 4280917 | D22: =M5 -> 3969935 | E22: =C22+D22 -> 8250852
B23: East Zone | C23: =Q5 -> 9270946 | D23: =R5 -> 8637373 | E23: =C23+D23 -> 17908319
B24: North East Zone | C24: =B9 -> 27541445 | D24: =C9 -> 26998878 | E24: =C24+D24 -> 54540323
B25: North Zone | C25: =L15 -> 32929570 | D25: =M15 -> 29958509 | E25: =C25+D25 -> 62888079
B26: South Zone | C26: =Q14 -> 31641265 | D26: =R14 -> 30410379 | E26: =C26+D26 -> 62051644
B27: West Zone | C27: =G6 -> 46436043 | D27: =H6 -> 42941495 | E27: =C27+D27 -> 89377538
B28: Total | C28: =SUM(C22:C27) -> 152100186 | D28: =SUM(D22:D27) -> 142916569 | E28: =C28+D28 -> 295016755
